Workbook

Sheet BILAN 
A1: Nom de l'entreprise:
A2: Secteur d'activité:
A3: BILAN
A4: REF | B4: ACTIF | E4: NOTE | F4: 31/12/N | I4: 31/12/N-1 | J4: 31/12/N-2 | K4: REF | L4: PASSIF | M4: NOTE | N4: =F4 -> 31/12/N | O4: =I4 -> 31/12/N-1 | P4: =J4 -> 31/12/N-2
F6: BRUT | G6: AMORT et DEPREC. | H6: NET | I6: NET | J6: NET | N6: NET | O6: NET | P6: NET
A7: AD | B7: IMMOBILISATIONS INCORPORELLES | E7: 3 | F7: =SUM(F8:F11) -> 0 | G7: =SUM(G8:G11) -> 0 | H7: =SUM(H8:H11) -> 0 | I7: =SUM(I8:I11) -> 0 | J7: =SUM(J8:J11) -> 0 | K7: CA | L7: Capital | M7: 13
A8: AE | B8: Frais de développement et de prospection | H8: =+F8-G8 -> 0 | K8: CB | L8: Apporteurs capital non appelé (-) | M8: 13
A9: AF | B9: Brevets, licences, logiciels et droits similaires | H9: =F9-G9 -> 0 | K9: CD | L9: Primes liées au capital social | M9: 14
A10: AG | B10: Fonds commercial et droit au bail | H10: =F10-G10 -> 0 | K10: CE | L10: Ecarts de réévaluation | M10: 3e
A11: AH | B11: Autres immobilisations incorporelles | H11: =F11-G11 -> 0 | K11: CF | L11: Réserves indisponibles | M11: 14
A12: AI | B12: IMMOBILISATIONS CORPORELLES | E12: 3 | F12: =SUM(F13:F18) -> 0 | G12: =SUM(G13:G18) -> 0 | H12: =SUM(H13:H18) -> 0 | I12: =SUM(I13:I18) -> 0 | J12: =SUM(J13:J18) -> 0 | K12: CG | L12: Réserves libres | M12: 14
A13: AJ | B13: Terrains (1) dont Placement Net : | H13: =F13-G13 -> 0 | K13: CH | L13: Report à nouveau (+ ou -) | M13: 14
A14: AK | B14: Bâtiments(1) dont Placement Net : | H14: =F14-G14 -> 0 | K14: CJ | L14: Résultat net de l'exercice (bénéfice + ou perte -)
A15: AL | B15: Aménagements, agencements et installations | H15: =F15-G15 -> 0 | K15: CL | L15: Subventions d'investissement | M15: 15
A16: AM | B16: Matériel, mobilier et actifs biologiques | H16: =F16-G16 -> 0 | K16: CM | L16: Provisions réglementées | M16: 15
A17: AN | B17: Matériel de transport | H17: =F17-G17 -> 0 | K17: CP | L17: TOTAL CAPITAUX PROPRES ET RESSOURCES ASSIMILEES | N17: =SUM(N7:N16) -> 0 | O17: =SUM(O7:O16) -> 0 | P17: =SUM(P7:P16) -> 0
A18: AP | B18: AVANCES ET ACOMPTES VERSES SUR IMMOBILISATIONS | E18: 3 | H18: =F18-G18 -> 0 | K18: DA | L18: Emprunts et dettes financières diverses | M18: 16
A19: AQ | B19: IMMOBILISATIONS FINANCIERES | E19: 4 | F19: =SUM(F20:F21) -> 0 | G19: =SUM(G20:G21) -> 0 | H19: =SUM(H20:H21) -> 0 | I19: =SUM(I20:I21) -> 0 | J19: =SUM(J20:J21) -> 0 | K19: DB | L19: Dettes de location-acquisition | M19: 16
A20: AR | B20: Titres de participation | H20: =F20-G20 -> 0 | K20: DC | L20: Provisions pour risques et charges | M20: 16
A21: AS | B21: Autres immobilisations financières | H21: =F21-G21 -> 0 | K21: DD | L21: TOTAL DETTES FINANCIERES ET RESSOURCES ASSIMILEES | N21: =SUM(N18:N20) -> 0 | O21: =SUM(O18:O20) -> 0 | P21: =SUM(P18:P20) -> 0
A22: AZ | B22: TOTAL ACTIF IMMOBILISE | F22: =F7+F12+F19 -> 0 | G22: =G7+G12+G19 -> 0 | H22: =H7+H12+H19 -> 0 | I22: =I7+I12+I19 -> 0 | J22: =J7+J12+J19 -> 0 | K22: DF | L22: TOTAL RESSOURCES STABLES | N22: =N17+N21 -> 0 | O22: =O17+O21 -> 0 | P22: =P17+P21 -> 0
A23: BA | B23: ACTIF CIRCULANT HAO | E23: 5 | H23: =F23-G23 -> 0 | K23: DH | L23: Dettes circulantes HAO | M23: 5
A24: BB | B24: STOCKS ET ENCOURS | E24: 6 | H24: =F24-G24 -> 0 | K24: DI | L24: Clients, avances reçues | M24: 7
A25: BG | B25: CREANCES ET EMPLOIS ASSIMILES | F25: =F26+F27+F28 -> 0 | G25: =G26+G27+G28 -> 0 | H25: =H26+H27+H28 -> 0 | I25: =I26+I27+I28 -> 0 | J25: =J26+J27+J28 -> 0 | K25: DJ | L25: Fournisseurs d'exploitation | M25: 17
A26: BH | B26: Fournisseurs avances versées | E26: 17 | H26: =F26-G26 -> 0 | K26: DK | L26: Dettes fiscales et sociales | M26: 18
A27: BI | B27: Clients | E27: 7 | H27: =F27-G27 -> 0 | K27: DM | L27: Autres dettes | M27: 19
A28: BJ | B28: Autres créances | E28: 8 | H28: =F28-G28 -> 0 | K28: DN | L28: Provisions pour risques et charges à court terme | M28: 19
A29: BK | B29: TOTAL ACTIF CIRCULANT | F29: =F23+F24+F25 -> 0 | G29: =G23+G24+G25 -> 0 | H29: =H23+H24+H25 -> 0 | I29: =I23+I24+I25 -> 0 | J29: =J23+J24+J25 -> 0 | K29: DP | L29: TOTAL PASSIF CIRCULANT | N29: =SUM(N23:N28) -> 0 | O29: =SUM(O23:O28) -> 0 | P29: =SUM(P23:P28) -> 0
A30: BQ | B30: Titres de placement | E30: 9 | H30: =F30-G30 -> 0
A31: BR | B31: Valeurs à encaisser | E31: 10 | H31: =F31-G31 -> 0 | K31: DQ | L31: Banques, crédits d'escompte | M31: 20
A32: BS | B32: Banques, chèques postaux, caisse et assimilés | E32: 11 | H32: =F32-G32 -> 0 | K32: DR | L32: Banques, établissements financiers et crédits de trésorerie | M32: 20
A33: BT | B33: TOTAL TRESORERIE-ACTIF | F33: =SUM(F30:F32) -> 0 | G33: =SUM(G30:G32) -> 0 | H33: =SUM(H30:H32) -> 0 | I33: =SUM(I30:I32) -> 0 | J33: =SUM(J30:J32) -> 0 | K33: DT | L33: TOTAL TRESORERIE-PASSIF | N33: =SUM(N31:N32) -> 0 | O33: =SUM(O31:O32) -> 0 | P33: =SUM(P31:P32) -> 0
A34: BU | B34: Ecart de conversion-Actif | E34: 12 | H34: =F34-G34 -> 0 | K34: DV | L34: Ecart de conversion-Passif | M34: 12
A35: BZ | B35: TOTAL GENERAL | F35: =F22+F29+F33+F34 -> 0 | G35: =G22+G29+G33+G34 -> 0 | H35: =H22+H29+H33+H34 -> 0 | I35: =I22+I29+I33+I34 -> 0 | J35: =J22+J29+J33+J34 -> 0 | K35: DZ | L35: TOTAL GENERAL | N35: =N22+N29+N33+N34 -> 0 | O35: =O22+O29+O33+O34 -> 0 | P35: =P22+P29+P33+P34 -> 0
F36: Contrôle | H36: =+H35-N35 -> 0 | I36: =+I35-O35 -> 0 | J36: =+J35-P35 -> 0

Sheet C.RESULTAT
C3: Exercice clos le : | G3: Durée (en mois) : | H3: 12
A5: COMPTE DE RESULTAT
A6: REF | B6: LIBELLES | G6: (2) | H6: NOTE | I6: ='BILAN '!N4 -> 31/12/N | J6: ='BILAN '!O4 -> 31/12/N-1 | K6: ='BILAN '!P4 -> 31/12/N-2
I8: NET (1) | J8: NET (1) | K8: NET (1)
A9: TA | B9: Ventes de marchandises | F9: A | G9: + | H9: 21
A10: RA | B10: Achats de marchandises | G10: - | H10: 22
A11: RB | B11: Variation de stocks de marchandises | G11: -/+ | H11: 6
A12: XA | B12: MARGE COMMERCIALE (Somme TA à RB) | I12: =SUM(I9:I11) -> 0 | J12: =IFERROR(SUM(J9:J11),"") -> 0 | K12: =IFERROR(SUM(K9:K11),"") -> 0
A13: TB | B13: Ventes de produits fabriqués | F13: B | G13: + | H13: 21
A14: TC | B14: Travaux, services vendus | F14: C | G14: + | H14: 21
A15: TD | B15: Produits accessoires | F15: D | G15: + | H15: 21
A16: XB | B16: CHIFFRE D'AFFAIRES (A + B + C + D) | I16: =I9+I13+I14+I15 -> 0 | J16: =IFERROR(J9+J13+J14+J15,"") -> 0 | K16: =IFERROR(K9+K13+K14+K15,"") -> 0
A17: TE | B17: Production stockée (ou déstockage) | G17: -/+ | H17: 6
A18: TF | B18: Production immobilisée | G18: + | H18: 21
A19: TG | B19: Subventions d’exploitation | G19: + | H19: 21
A20: TH | B20: Autres produits | G20: + | H20: 21
A21: TI | B21: Transferts de charges d'exploitation | G21: + | H21: 12
A22: RC | B22: Achats de matières premières et fournitures liées | G22: - | H22: 22
A23: RD | B23: Variation de stocks de matières premières et fournitures liées | G23: -/+ | H23: 6
A24: RE | B24: Autres achats | G24: - | H24: 22
A25: RF | B25: Variation de stocks d’autres approvisionnements | G25: -/+ | H25: 6
A26: RG | B26: Transports | G26: - | H26: 23
A27: RH | B27: Services extérieurs | G27: - | H27: 24
A28: RI | B28: Impôts et taxes | G28: - | H28: 25
A29: RJ | B29: Autres charges | G29: - | H29: 26
A30: XC | B30: VALEUR AJOUTEE (XB +RA+RB) + (somme TE à RJ) | I30: =SUM(I17:I29) +I10+I11+I16 -> 0 | J30: =IFERROR(SUM(J17:J29) +J10+J11+J16,"") -> 0 | K30: =IFERROR(SUM(K17:K29) +K10+K11+K16,"") -> 0
A31: RK | B31: Charges de personnel | G31: - | H31: 27
A32: XD | B32: EXCEDENT BRUT D'EXPLOITATION (XC+RK) | I32: =I30+I31 -> 0 | J32: =IFERROR(J30+J31,"") -> 0 | K32: =IFERROR(K30+K31,"") -> 0
A33: TJ | B33: Reprises d’amortissements, provisions et dépréciations | G33: + | H33: 28
A34: RL | B34: Dotations aux amortissements, aux provisions et dépréciations | G34: - | H34: 3C&28
A35: XE | B35: RESULTAT D'EXPLOITATION (XD+TJ+ RL) | I35: =I32+I33+I34 -> 0 | J35: =J32+J33+J34 -> 0 | K35: =IFERROR(K32+K33+K34,"") -> 0
A36: TK | B36: Revenus financiers et assimilés | G36: + | H36: 29
A37: TL | B37: Reprises de provisions et dépréciations financières | G37: + | H37: 28
A38: TM | B38: Transferts de charges financières | G38: + | H38: 12
A39: RM | B39: Frais financiers et charges assimilées | G39: - | H39: 29
A40: RN | B40: Dotations aux provisions et aux dépréciations financières | G40: - | H40: 3C&28
A41: XF | B41: RESULTAT FINANCIER (somme TK à RN) | I41: =SUM(I36:I40) -> 0 | J41: =IFERROR(SUM(J36:J40),"") -> 0 | K41: =IFERROR(SUM(K36:K40),"") -> 0
A42: XG | B42: RESULTAT DES ACTIVITES ORDINAIRES (XE+XF) | I42: =I35+I41 -> 0 | J42: =IFERROR(J35+J41,"") -> 0 | K42: =IFERROR(K35+K41,"") -> 0
A43: TN | B43: Produits des cessions d'immobilisations | G43: + | H43: 3D
A44: TO | B44: Autres Produits HAO | G44: + | H44: 30
...

Sheet TFT
A1: - 0 -
H2: FLUX DE TRESORERIE SYSTEME NORMAL PAGE 1/1
E5: Exercice clos le : | I5: Durée (en mois) : | J5: 12
A7: TABLEAU DES FLUX DE TRESORERIE
A8: REF | B8: LIBELLES | H8: NOTE | I8: EXERCICE | J8: EXERCICE | K8: EXERCICE
I9: N | J9: N-1 | K9: N-2
A10: ZA | B10: Trésorerie nette au 1er janvier (Trésorerie actif N-1 - Trésorerie passif N-1) | G10: A
B11: Flux de trésorerie provenant des activités opérationnelles
A12: FA | B12: Capacité d'Autofinancement Globale (CAFG)
A13: FB | B13: - Variation d'actif circulant HAO (1)
A14: FC | B14: - Variation des stocks
A15: FD | B15: - Variation des créances
A16: FE | B16: + Variation du passif circulant (1)
B17: Variation du BF lié aux activités opérationnelles
B18: FB+FC+FD+FE : | C18: =I13+I14+I15+I16 -> 0 | E18: =IFERROR(J13+J14+J15+J16,"") -> 0
A19: ZB | B19: Flux de trésorerie provenant des activités opérationnelles (Somme FA à FE) | G19: B | I19: =SUM(I12:I16) -> 0 | J19: =IFERROR(SUM(J12:J16),"") -> 0 | K19: =IFERROR(SUM(K12:K16),"") -> 0
B20: Flux de trésorerie provenant des activités d’investissements
A21: FF | B21: - Décaissements liés aux acquisitions d'immobilisations incorporelles
A22: FG | B22: - Décaissements liés aux acquisitions d'immobilisations corporelles
A23: FH | B23: - Décaissements liés aux acquisitions d'immobilisations financières
A24: FI | B24: + Encaissements liés aux cessions d’immobilisations incorporelles et corporelles
A25: FJ | B25: + Encaissements liés aux cessions d’immobilisations financières
A26: ZC | B26: Flux de trésorerie provenant des activités d’investissement (somme FF à FJ) | G26: C | I26: =SUM(I21:I25) -> 0 | J26: =IFERROR(SUM(J21:J25),"") -> 0 | K26: =IFERROR(SUM(K21:K25),"") -> 0
B27: Flux de trésorerie provenant du financement par les capitaux propres
A28: FK | B28: + Augmentations de capital par apports nouveaux
A29: FL | B29: + Subventions d'investissement reçues
A30: FM | B30: - Prélèvements sur le capital
A31: FN | B31: - Dividendes versés
A32: ZD | B32: Flux de trésorerie provenant des capitaux propres (somme FK à FN) | G32: D | I32: =SUM(I28:I31) -> 0 | J32: =IFERROR(SUM(J28:J31),"") -> 0 | K32: =IFERROR(SUM(K28:K31),"") -> 0
B33: Trésorerie provenant du financement par les capitaux étrangers
A34: FO | B34: + Emprunts (2)
A35: FP | B35: + Autres dettes financières diverses (3)
A36: FQ | B36: - Remboursements des emprunts et autres dettes financières
A37: ZE | B37: Flux de trésorerie provenant des capitaux étrangers (somme FO à FQ) | G37: E | I37: =SUM(I34:I36) -> 0 | J37: =IFERROR(SUM(J34:J36),"") -> 0 | K37: =IFERROR(SUM(K34:K36),"") -> 0
A38: ZF | B38: Flux de trésorerie provenant des activités de financement (D+E) | G38: F | I38: =I32+I37 -> 0 | J38: =IFERROR(J32+J37,"") -> 0 | K38: =IFERROR(K32+K37,"") -> 0
A39: ZG | B39: VARIATION DE LA TRÉSORERIE NETTE DE LA PÉRIODE (B+C+F) | G39: G | I39: =I19+I26+I38 -> 0 | J39: =J19+J26+J38 -> 0 | K39: =K19+K26+K38 -> 0
A40: ZH | B40: Trésorerie nette au 31 Décembre (G+A) | G40: H | I40: =I10+I39 -> 0 | J40: =IFERROR(J10+J39,"") -> 0 | K40: =IFERROR(K10+K39,"") -> 0
B41: Contrôle : Trésorerie actif N - Trésorerie passif N | I41: =+'BILAN '!H33-'BILAN '!N33 -> 0 | J41: =+'BILAN '!I33-'BILAN '!O33 -> 0 | K41: =+'BILAN '!J33-'BILAN '!P33 -> 0
A42: (1) | B42: A l’exclusion des variations des créances et dettes liées aux activités d’investissement (variation des créances sur cession d’immobilisation et des dettes sur acquisition ou production d’immobilisation) et de financement (par exemple variation des créances sur subventions d’investissements reçues).
A43: (2) | B43: Comptes 161, 162, 1661, 1662
...

Sheet Accords de classement
A2: ACCORD DE CLASSEMENT BCEAO : RATIOS DE DECISION
A3: RATIOS | B3: FORMULES | C3: ='BILAN '!N4 -> 31/12/N | D3: ='BILAN '!O4 -> 31/12/N-1 | E3: =+[1]BILAN!J4 -> 45291 | F3: NORME | G3: OBSERVATION
A4: AUTONOMIE FINANCIERE | B4: Ressources propres / Total Passif | C4: =+'BILAN '!N17/'BILAN '!N35 -> #DIV/0! | D4: =+'BILAN '!O17/'BILAN '!O35 -> #DIV/0! | E4: =+[1]BILAN!P17/[1]BILAN!P35 -> 0.12094695 | F4: Minimum 20% | G4: =IF(C4<=20%,"Non respecté.","Respecté.") -> #DIV/0!
A5: CAPACITE DE REMBOURSEMENT | B5: Dettes financières et ressources assimilées / CAF | C5: ='BILAN '!N21/'Résume Financier'!C10 -> #DIV/0! | D5: ='BILAN '!O21/'Résume Financier'!D10 -> #DIV/0! | E5: =[1]BILAN!P21/[1]Carnevas!E10 -> 4.533406 | F5: Inférieur ou égal à 4 | G5: =IF(C5<=4," Respecté"," Non respecté.") -> #DIV/0!
A6: RENTABILITE | B6: Résultat net / CA hors taxes | C6: =+C.RESULTAT!I50/C.RESULTAT!I16 -> #DIV/0! | D6: =+C.RESULTAT!J50/C.RESULTAT!J16 -> #DIV/0! | E6: =+[1]C.RESULTAT!K50/[1]C.RESULTAT!K16 -> 0.019659507 | F6: Supérieur à 0 | G6: =IF(C6>=0,"Respecté.","Respecté.") -> #DIV/0!
A7: LIQUIDITE GENERALE | B7: Total Actif circulant net incluant le total Trésorerie Actif / Total Passif circulant incluant le total Trésorerie Passif | C7: =('BILAN '!H29-'BILAN '!H33)/('BILAN '!N29-'BILAN '!N33) -> #DIV/0! | D7: =('BILAN '!I29-'BILAN '!I33)/('BILAN '!O29-'BILAN '!O33) -> #DIV/0! | E7: =+([1]BILAN!J29+[1]BILAN!J33)/([1]BILAN!P29+[1]BILAN!P33) -> 1.3013196 | F7: Supérieur à 1 | G7: =+IF(C7<1,"Non respecté","Respecté") -> #DIV/0!

Sheet Ratios 
A1: ACCORD DE CLASSEMENT BCEAO : RATIOS D'OBSERVATION
A2: RATIOS | B2: FORMULES | C2: ='BILAN '!N4 -> 31/12/N | D2: ='BILAN '!O4 -> 31/12/N-1 | E2: ='BILAN '!P4 -> 31/12/N-2 | F2: NORME
A3: ROTATION DES STOCKS | B3: (Stock moyen de matières premières / Achats de matières premières HT)x360 | C3: =+('BILAN '!H24*360)/C.RESULTAT!I16 -> #DIV/0! | D3: =+('BILAN '!I24*360)/C.RESULTAT!J16 -> #DIV/0! | E3: =+('BILAN '!J24*360)/C.RESULTAT!K16 -> #DIV/0! | F3: =IF(C3<=30,"Risque faible car court délai d'écoulement des produits en stock","Risque élevé car long délai d'écoulement des produits en stock") -> #DIV/0!
A4: DELAI CLIENTS | B4: ((Clients - Avances reçues de la clientèle) / Chiffre d'affaires TTC)*360 | C4: =+((('BILAN '!H27-'BILAN '!N24)/C.RESULTAT!I16)*360) -> #DIV/0! | D4: =+((('BILAN '!I27-'BILAN '!O24)/C.RESULTAT!J16)*360) -> #DIV/0! | E4: =+((('BILAN '!J27-'BILAN '!P24)/C.RESULTAT!K16)*360) -> #DIV/0! | F4: =IF(C4<=30,"Risque faible car court délai d'encaissement des créances clients est mois d'un mois","Risque élevé car le long délai peut indiquer que certains clients sont en difficultés de paiement et/ou montre des difficultées de trésorerie causes d'un mauvais recouvrement.") -> #DIV/0!
A5: DELAI FOURNISSEURS | B5: ((Fournisseurs d'exploitation - Avances versées sur commandes)/Achats TTC)x360 | C5: =(('BILAN '!N25-'BILAN '!H26)/-(C.RESULTAT!I10+C.RESULTAT!I22+C.RESULTAT!I24))*360 -> #DIV/0! | D5: =(('BILAN '!O25-'BILAN '!I26)/-(C.RESULTAT!J10+C.RESULTAT!J22+C.RESULTAT!J24))*360 -> #DIV/0! | E5: =(('BILAN '!P25-'BILAN '!J26)/-(C.RESULTAT!K10+C.RESULTAT!K22+C.RESULTAT!K24))*360 -> #DIV/0! | F5: =IF(C5<=30,"Risque faible, cela peut etre une source de financement et un indicateur de bonne gestion de sa trésorerie.","Risque élevé, cela peut mettre en lumièere un manque de trésorerie pour regler ses fournisseurs.") -> #DIV/0!
A6: RATIO D'EQUILIBRE FINANCIER | B6: Fonds de roulement / Besoin de financement global | C6: =('BILAN '!N22-'BILAN '!H22)/('BILAN '!H29-'BILAN '!N29) -> #DIV/0! | D6: =('BILAN '!O22-'BILAN '!I22)/('BILAN '!I29-'BILAN '!O29) -> #DIV/0! | E6: =('BILAN '!P22-'BILAN '!J22)/('BILAN '!J29-'BILAN '!P29) -> #DIV/0!

Sheet Résume Financier
B1: Données financières I | C1: ='BILAN '!N4 -> 31/12/N | D1: ='BILAN '!O4 -> 31/12/N-1 | E1: ='BILAN '!P4 -> 31/12/N-2 | F1: Variations % | G1: Variations %
B2: Total Bilan | C2: =+'BILAN '!H35 -> 0 | D2: =+'BILAN '!I35 -> 0 | E2: =+'BILAN '!J35 -> 0 | F2: =+(C2-D2)/D2 -> #DIV/0! | G2: =+(D2-E2)/E2 -> #DIV/0!
B3: Fonds Propres Nets | C3: =+'BILAN '!N17 -> 0 | D3: =+'BILAN '!O17 -> 0 | E3: =+'BILAN '!P17 -> 0 | F3: =+(C3-D3)/D3 -> #DIV/0! | G3: =+(D3-E3)/E3 -> #DIV/0!
B4: Fonds de roulement | C4: =+'BILAN '!N22-'BILAN '!H22 -> 0 | D4: =+'BILAN '!O22-'BILAN '!I22 -> 0 | E4: =+'BILAN '!P22-'BILAN '!J22 -> 0 | F4: =+(C4-D4)/D4 -> #DIV/0! | G4: =+(D4-E4)/E4 -> #DIV/0!
B5: Dettes financières inclus Hors bilan | C5: =+'BILAN '!N21 -> 0 | D5: =+'BILAN '!O21 -> 0 | E5: =+'BILAN '!P21 -> 0 | F5: =+(C5-D5)/D5 -> #DIV/0! | G5: =+(D5-E5)/E5 -> #DIV/0!
B6: Autonomie Financière (Capitaux propres/Endettement total) | C6: =+'BILAN '!N17/'BILAN '!N21 -> #DIV/0! | D6: =+'BILAN '!O17/'BILAN '!O21 -> #DIV/0! | E6: =+'BILAN '!P17/'BILAN '!P21 -> #DIV/0! | F6: =+(C6-D6)/D6 -> #DIV/0! | G6: =+(D6-E6)/E6 -> #DIV/0!
B7: Chiffre d’affaires | C7: =C.RESULTAT!I16 -> 0 | D7: =C.RESULTAT!J16 -> 0 | E7: =C.RESULTAT!K16 -> 0 | F7: =+(C7-D7)/D7 -> #DIV/0! | G7: =+(D7-E7)/E7 -> #DIV/0!
B8: Excédent Brut d’Exploitation (EBE) | C8: =C.RESULTAT!I32 -> 0 | D8: =C.RESULTAT!J32 -> 0 | E8: =C.RESULTAT!K32 -> 0 | F8: =+(C8-D8)/D8 -> #DIV/0! | G8: =+(D8-E8)/E8 -> #DIV/0!
B9: Résultat d’Exploitation (EBIT) | C9: =C.RESULTAT!I35 -> 0 | D9: =C.RESULTAT!J35 -> 0 | E9: =C.RESULTAT!K35 -> 0 | F9: =+(C9-D9)/D9 -> #DIV/0! | G9: =+(D9-E9)/E9 -> #DIV/0!
B10: Cash Flow (CAF) | C10: =+(C.RESULTAT!I50+C.RESULTAT!I34-C.RESULTAT!I33+C.RESULTAT!I45-C.RESULTAT!I43) -> 0 | D10: =+(C.RESULTAT!J50+C.RESULTAT!J34-C.RESULTAT!J33+C.RESULTAT!J45-C.RESULTAT!J43) -> 0 | E10: =+(C.RESULTAT!K50+C.RESULTAT!K34-C.RESULTAT!K33+C.RESULTAT!K45-C.RESULTAT!K43) -> 0 | F10: =+(C10-D10)/D10 -> #DIV/0! | G10: =+(D10-E10)/E10 -> #DIV/0!
B11: Résultat Net | C11: =C.RESULTAT!I50 -> 0 | D11: =C.RESULTAT!J50 -> 0 | E11: =C.RESULTAT!K50 -> 0 | F11: =+(C11-D11)/D11 -> #DIV/0! | G11: =+(D11-E11)/E11 -> #DIV/0!
B12: Durée de remboursement Dettes (Dettes Fin/EBIT) [années] | C12: ='BILAN '!N21/C.RESULTAT!I35 -> #DIV/0! | D12: ='BILAN '!O21/C.RESULTAT!J35 -> #DIV/0! | E12: ='BILAN '!P21/C.RESULTAT!K35 -> #DIV/0! | F12: =+(C12-D12)/D12 -> #DIV/0! | G12: =+(D12-E12)/E12 -> #DIV/0!
B13: Couverture Intérêts (EBIT/Charges Intérêts) [x] | C13: =C.RESULTAT!I35/C.RESULTAT!I39 -> #DIV/0! | D13: =C.RESULTAT!J35/C.RESULTAT!J39 -> #DIV/0! | E13: =C.RESULTAT!K35/C.RESULTAT!K39 -> #DIV/0! | F13: =+(C13-D13)/D13 -> #DIV/0! | G13: =+(D13-E13)/E13 -> #DIV/0!
B14: =#REF! -> #REF!
B15: Données financières II | C15: =C1 -> 31/12/N | D15: =D1 -> 31/12/N-1 | E15: =E1 -> 31/12/N-2 | F15: Variations % | G15: Variations %
B16: Chiffre d’affaires | C16: =C.RESULTAT!I16 -> 0 | D16: =C.RESULTAT!J16 -> 0 | E16: =C.RESULTAT!K16 -> 0 | F16: =+(C16-D16)/D16 -> #DIV/0! | G16: =+(D16-E16)/E16 -> #DIV/0!
B17: Excédent Brut Exploitation (EBE) | C17: =C.RESULTAT!I32 -> 0 | D17: =C.RESULTAT!J32 -> 0 | E17: =C.RESULTAT!K32 -> 0 | F17: =+(C17-D17)/D17 -> #DIV/0! | G17: =+(D17-E17)/E17 -> #DIV/0!
B18: Résultat Exploitation (REX) | C18: =C.RESULTAT!I35 -> 0 | D18: =C.RESULTAT!J35 -> 0 | E18: =C.RESULTAT!K35 -> 0 | F18: =+(C18-D18)/D18 -> #DIV/0! | G18: =+(D18-E18)/E18 -> #DIV/0!
B19: Cash Flow | C19: =C10 -> 0 | D19: =D10 -> 0 | E19: =E10 -> 0 | F19: =+(C19-D19)/D19 -> #DIV/0! | G19: =+(D19-E19)/E19 -> #DIV/0!
B20: Frais financiers | C20: =C.RESULTAT!I39 -> 0 | D20: =C.RESULTAT!J39 -> 0 | E20: =C.RESULTAT!K39 -> 0 | F20: =+(C20-D20)/D20 -> #DIV/0! | G20: =+(D20-E20)/E20 -> #DIV/0!
B21: Résultat Net | C21: =C.RESULTAT!I50 -> 0 | D21: =C.RESULTAT!J50 -> 0 | E21: =C.RESULTAT!K50 -> 0 | F21: =+(C21-D21)/D21 -> #DIV/0! | G21: =+(D21-E21)/E21 -> #DIV/0!
B22: Total Dettes financières et ressources assimilées | C22: ='BILAN '!N21 -> 0 | D22: ='BILAN '!O21 -> 0 | E22: ='BILAN '!P21 -> 0 | F22: =+(C22-D22)/D22 -> #DIV/0! | G22: =+(D22-E22)/E22 -> #DIV/0!
B23: Dettes Financières/Total Bilan | C23: ='BILAN '!N18/'BILAN '!N35 -> #DIV/0! | D23: ='BILAN '!O18/'BILAN '!O35 -> #DIV/0! | E23: ='BILAN '!P18/'BILAN '!P35 -> #DIV/0! | F23: =+(C23-D23)/D23 -> #DIV/0! | G23: =+(D23-E23)/E23 -> #DIV/0!
B24: Fonds Propres | C24: ='BILAN '!N17 -> 0 | D24: ='BILAN '!O17 -> 0 | E24: ='BILAN '!P17 -> 0 | F24: =+(C24-D24)/D24 -> #DIV/0! | G24: =+(D24-E24)/E24 -> #DIV/0!
B25: Fonds Propres/Dettes Financières | C25: =C24/C22 -> #DIV/0! | D25: =D24/D22 -> #DIV/0! | E25: =E24/E22 -> #DIV/0! | F25: =+(C25-D25)/D25 -> #DIV/0! | G25: =+(D25-E25)/E25 -> #DIV/0!
B26: Frais Financiers/Chiffre d’affaires | C26: =-C20/C16 -> #DIV/0! | D26: =-D20/D16 -> #DIV/0! | E26: =-E20/E16 -> #DIV/0! | F26: =+(C26-D26)/D26 -> #DIV/0! | G26: =+(D26-E26)/E26 -> #DIV/0!
B27: Frais financiers/(REX) (frais fin/Resul exploi) | C27: =-C20/C18 -> #DIV/0! | D27: =-D20/D18 -> #DIV/0! | E27: =-E20/E18 -> #DIV/0! | F27: =+(C27-D27)/D27 -> #DIV/0! | G27: =+(D27-E27)/E27 -> #DIV/0!
B28: Poste Client | C28: =+'BILAN '!H27 -> 0 | D28: =+'BILAN '!I27 -> 0 | E28: =+'BILAN '!J27 -> 0 | F28: =+(C28-D28)/D28 -> #DIV/0! | G28: =+(D28-E28)/E28 -> #DIV/0!
B29: Fournisseurs | C29: =+'BILAN '!N25 -> 0 | D29: =+'BILAN '!O25 -> 0 | E29: =+'BILAN '!P25 -> 0 | F29: =+(C29-D29)/D29 -> #DIV/0! | G29: =+(D29-E29)/E29 -> #DIV/0!
B30: Fonds de roulement | C30: =+'BILAN '!N22-'BILAN '!H22 -> 0 | D30: =+'BILAN '!O22-'BILAN '!I22 -> 0 | E30: =+'BILAN '!P22-'BILAN '!J22 -> 0 | F30: =+(C30-D30)/D30 -> #DIV/0! | G30: =+(D30-E30)/E30 -> #DIV/0!
B31: Besoin fonds de roulement | C31: =+'BILAN '!H29-'BILAN '!N29 -> 0 | D31: =+'BILAN '!I29-'BILAN '!O29 -> 0 | E31: =+'BILAN '!J29-'BILAN '!P29 -> 0 | F31: =+(C31-D31)/D31 -> #DIV/0! | G31: =+(D31-E31)/E31 -> #DIV/0!
B32: Rotation du stock | C32: =+'Ratios '!C3 -> #DIV/0! | D32: =+'Ratios '!D3 -> #DIV/0! | E32: =+'Ratios '!E3 -> #DIV/0! | F32: =+AVERAGE(C32:D32) -> #DIV/0! | G32: =+AVERAGE(D32:E32) -> #DIV/0!
B33: Délai fournisseur | C33: ='Ratios '!C5 -> #DIV/0! | D33: ='Ratios '!D5 -> #DIV/0! | E33: ='Ratios '!E5 -> #DIV/0! | F33: =+AVERAGE(C33:D33) -> #DIV/0! | G33: =+AVERAGE(D33:E33) -> #DIV/0!
B34: Délai Client | C34: ='Ratios '!C4 -> #DIV/0! | D34: ='Ratios '!D4 -> #DIV/0! | E34: ='Ratios '!E4 -> #DIV/0! | F34: =+AVERAGE(C34:D34) -> #DIV/0! | G34: =+AVERAGE(D34:E34) -> #DIV/0!
B36: Risk Asset Acceptance Criteria (RAAC/CARC) | E36: Minimum | H36: Maximum
E37: Tiers I | F37: Tiers II | G37: Tiers III | H37: Tiers I | I37: Tiers II | J37: Tiers III
E38: Moyenne calculée sur les données du secteur comme Norme | H38: Moyenne calculée sur les données du secteur comme Norme
B39: EBITDA (EBE)/CA (rentabilité op %) (qui permet de mesurer le niveau de rentabilité du processus d’exploitation d’une entreprise) | C39: =C17/C16 -> #DIV/0! | D39: =D17/D16 -> #DIV/0! | E39: 15 | F39: 20 | G39: 30 | H39: 20 | I39: 30 | J39: 40
B40: Capitaux propres/Capitaux permanentsAutonomie fin (qui permet de connaitre la capacité de l'entreprise à se financer par ses propres moyens) | C40: ='BILAN '!N17/'BILAN '!N22 -> #DIV/0! | D40: ='BILAN '!O17/'BILAN '!O22 -> #DIV/0! | E40: > 20 % | F40: > 30 % | G40: > 50 % | H40: > 50 % | I40: > 50 % | J40: > 50 %
B41: Dettes financières et ressources Ass / CAF (ratio de capacité de remboursement): pour évaluer votre capacité à rembourser vos dettes. | C41: =C22/C10 -> #DIV/0! | D41: =D22/D10 -> #DIV/0! | E41: <= 2 | F41: <= 3 | G41: <= 4 | H41: <= 3 | I41: <= 4 | J41: <= 4
...
